Workbook

Sheet README
A1: Recall experiment (02464 AI and Human Cognition) – clean dataset
A2: Built from '02464_project 1.xlsx'. The 0/1 data are unchanged; only the layout, the language and a few formula errors were fixed (see Data notes).
A4: Design
A5: Participants | B5: Bertram, Lasse, Noah, Vincent, Filippa (5)
A6: Trials | B6: 5 per participant per condition = 25 trials per condition
A7: Free recall | B7: 15-word lists → positions 1–15
A8: Serial recall | B8: 10-word lists → positions 1–10
A10: Coding (one cell = one word in one trial)
A11: 1 / 0 | B11: 1 = recalled, 0 = not recalled
A12: Free recall | B12: 1 if the word was reported at any point during recall. Position = PRESENTATION position, not the order in which it was reported.
A13: Serial recall | B13: 1 only if the correct word was reported in the correct position.
A15: Sheets
A16: Sheet | B16: Contents | C16: Details | D16: Size
A17: FR1_Control … FR4_EmptyDelay | B17: Raw free recall data, one sheet per condition | C17: Rows = serial position, columns = trials (Participant_Trial). Last column 'Row mean' = proportion recalled at that position (formula). | D17: 15 × 25
A18: SR1_Control … SR4_Tapping | B18: Raw serial recall data, one sheet per condition | C18: Same layout as the free recall sheets. | D18: 10 × 25
A19: FR_PositionMeans, SR_PositionMeans | B19: Serial position curves | C19: The 'Row mean' columns of all conditions side by side (primacy / recency). Last row = overall mean recall per condition. | D19: positions × 4
A20: FR_TrialScores, SR_TrialScores | B20: Score per trial (input for the ANOVA) | C20: Proportion of list words recalled in each trial (column mean of the raw sheet). One row per trial. | D20: 25 × 4
A21: Pilot_FR | B21: Pilot free recall run | C21: One list per condition. Not part of the main analysis. | D21: 15 × 4
A23: Conditions
A24: Sheet | B24: Condition | C24: Title in the original file | D24: Task
A25: FR1_Control | B25: Control – 1 word per 2 s | C25: FR1 - Kontrol - 1 ord/ 2.sekund | D25: Free recall
A26: FR2_Fast | B26: Fast presentation – 500 ms per word | C26: FR2 - Hurtig praesentation - 500 ms/ord | D26: Free recall
A27: FR3_FilledDelay | B27: Filled delay – counting the 3-times table | C27: FR3 - Udfyldt pause -3 tabellen | D27: Free recall
A28: FR4_EmptyDelay | B28: Empty delay – 30 s of silence | C28: FR4 - Tom pause - 30 s stilhed | D28: Free recall
A29: SR1_Control | B29: Control | C29: SR1 - Kontrol | D29: Serial recall
A30: SR2_Chunking | B30: Chunking | C30: SR1 - Chunking (labelled SR1 in the original by mistake) | D30: Serial recall
A31: SR3_Suppression | B31: Articulatory suppression | C31: SR3 - Artikulatorisk suppression | D31: Serial recall
A32: SR4_Tapping | B32: Finger tapping | C32: SR4 - Fingertapning | D32: Serial recall
A34: Data notes
A35: Note 1 | B35: Empty cells in the data grid were set to 0. The original totals ('Korrekte i alt') confirm that an empty cell meant 'not recalled'. This matters: Excel's AVERAGE skips empty cells, so leaving them empty would overestimate recall.
A36: Note 2 | B36: Fixed: SR2_Chunking, Noah trial 4. The original total formula was =SUM(O26:O34), which skips Position 1, so the sheet showed 9/10. The raw data say 10/10.
A37: Note 3 | B37: SR2_Chunking, Noah trial 3: the original total was typed in as the number 10 instead of a formula (the value was correct).
A38: Note 4 | B38: FR2_Fast, Filippa trial 5: the proportion cell was empty in the original (3/15 = 0.200).
A39: Note 5 | B39: Serial recall error-type rows (transpositions, omissions, intrusions, phonological) were empty in the original and are not included.
A40: Note 6 | B40: The original instructions planned five serial recall blocks with 6- or 9-word lists. The collected data contain four blocks, each scored over 10 positions (the original sheet also divided by 10).
A41: Note 7 | B41: Unused template columns (AF:BI in 'Free recall') and the empty 'Serial recall' heading in the pilot sheet were removed.
A43: Reading the data in Python
B44: import pandas as pd
B45: df = pd.read_excel("02464_recall_data_clean.xlsx", sheet_name="FR1_Control")
B46: data = df.iloc[:, 1:26].to_numpy() # 15 x 25 array of 0/1 (only the trial columns)
...

Sheet FR1_Control
A1: Position | B1: Bertram_T1 | C1: Bertram_T2 | D1: Bertram_T3 | E1: Bertram_T4 | F1: Bertram_T5 | G1: Lasse_T1 | H1: Lasse_T2 | I1: Lasse_T3 | J1: Lasse_T4 | K1: Lasse_T5 | L1: Noah_T1 | M1: Noah_T2 | N1: Noah_T3 | O1: Noah_T4 | P1: Noah_T5 | Q1: Vincent_T1 | R1: Vincent_T2 | S1: Vincent_T3 | T1: Vincent_T4 | U1: Vincent_T5 | V1: Filippa_T1 | W1: Filippa_T2 | X1: Filippa_T3 | Y1: Filippa_T4 | Z1: Filippa_T5 | AA1: Row mean
A2: 1 | B2: 1 | C2: 1 | D2: 0 | E2: 1 | F2: 0 | G2: 1 | H2: 1 | I2: 1 | J2: 1 | K2: 1 | L2: 0 | M2: 0 | N2: 0 | O2: 1 | P2: 0 | Q2: 1 | R2: 1 | S2: 1 | T2: 1 | U2: 1 | V2: 1 | W2: 0 | X2: 0 | Y2: 1 | Z2: 0 | AA2: =AVERAGE(B2:Z2) -> 0.64
A3: 2 | B3: 0 | C3: 1 | D3: 0 | E3: 1 | F3: 0 | G3: 1 | H3: 1 | I3: 0 | J3: 0 | K3: 0 | L3: 1 | M3: 1 | N3: 1 | O3: 1 | P3: 0 | Q3: 1 | R3: 1 | S3: 1 | T3: 1 | U3: 1 | V3: 0 | W3: 0 | X3: 0 | Y3: 0 | Z3: 0 | AA3: =AVERAGE(B3:Z3) -> 0.52
A4: 3 | B4: 1 | C4: 0 | D4: 0 | E4: 0 | F4: 0 | G4: 1 | H4: 1 | I4: 0 | J4: 1 | K4: 1 | L4: 1 | M4: 0 | N4: 1 | O4: 1 | P4: 0 | Q4: 1 | R4: 1 | S4: 1 | T4: 1 | U4: 1 | V4: 1 | W4: 0 | X4: 0 | Y4: 1 | Z4: 0 | AA4: =AVERAGE(B4:Z4) -> 0.6
A5: 4 | B5: 1 | C5: 1 | D5: 0 | E5: 0 | F5: 0 | G5: 1 | H5: 0 | I5: 0 | J5: 1 | K5: 1 | L5: 1 | M5: 1 | N5: 0 | O5: 0 | P5: 0 | Q5: 1 | R5: 0 | S5: 1 | T5: 1 | U5: 0 | V5: 0 | W5: 0 | X5: 0 | Y5: 1 | Z5: 0 | AA5: =AVERAGE(B5:Z5) -> 0.44
A6: 5 | B6: 0 | C6: 0 | D6: 0 | E6: 0 | F6: 0 | G6: 0 | H6: 0 | I6: 0 | J6: 0 | K6: 0 | L6: 0 | M6: 0 | N6: 1 | O6: 1 | P6: 1 | Q6: 1 | R6: 1 | S6: 1 | T6: 1 | U6: 1 | V6: 0 | W6: 1 | X6: 1 | Y6: 0 | Z6: 1 | AA6: =AVERAGE(B6:Z6) -> 0.44
A7: 6 | B7: 1 | C7: 0 | D7: 0 | E7: 0 | F7: 0 | G7: 0 | H7: 1 | I7: 0 | J7: 0 | K7: 0 | L7: 0 | M7: 0 | N7: 0 | O7: 1 | P7: 0 | Q7: 1 | R7: 0 | S7: 0 | T7: 0 | U7: 1 | V7: 0 | W7: 1 | X7: 1 | Y7: 1 | Z7: 0 | AA7: =AVERAGE(B7:Z7) -> 0.32
A8: 7 | B8: 0 | C8: 1 | D8: 0 | E8: 1 | F8: 0 | G8: 0 | H8: 0 | I8: 0 | J8: 0 | K8: 0 | L8: 1 | M8: 1 | N8: 0 | O8: 0 | P8: 0 | Q8: 0 | R8: 1 | S8: 0 | T8: 0 | U8: 0 | V8: 0 | W8: 0 | X8: 1 | Y8: 1 | Z8: 0 | AA8: =AVERAGE(B8:Z8) -> 0.28
A9: 8 | B9: 0 | C9: 0 | D9: 0 | E9: 0 | F9: 1 | G9: 0 | H9: 0 | I9: 1 | J9: 1 | K9: 0 | L9: 0 | M9: 1 | N9: 0 | O9: 0 | P9: 0 | Q9: 0 | R9: 1 | S9: 0 | T9: 0 | U9: 0 | V9: 0 | W9: 1 | X9: 0 | Y9: 0 | Z9: 0 | AA9: =AVERAGE(B9:Z9) -> 0.24
A10: 9 | B10: 1 | C10: 0 | D10: 0 | E10: 1 | F10: 0 | G10: 1 | H10: 0 | I10: 0 | J10: 0 | K10: 1 | L10: 0 | M10: 0 | N10: 0 | O10: 1 | P10: 0 | Q10: 0 | R10: 1 | S10: 0 | T10: 0 | U10: 1 | V10: 1 | W10: 0 | X10: 0 | Y10: 0 | Z10: 1 | AA10: =AVERAGE(B10:Z10) -> 0.36
A11: 10 | B11: 1 | C11: 0 | D11: 1 | E11: 0 | F11: 1 | G11: 0 | H11: 0 | I11: 1 | J11: 0 | K11: 1 | L11: 0 | M11: 0 | N11: 0 | O11: 1 | P11: 1 | Q11: 0 | R11: 1 | S11: 0 | T11: 0 | U11: 0 | V11: 0 | W11: 0 | X11: 0 | Y11: 1 | Z11: 1 | AA11: =AVERAGE(B11:Z11) -> 0.4
A12: 11 | B12: 0 | C12: 0 | D12: 1 | E12: 0 | F12: 1 | G12: 0 | H12: 0 | I12: 0 | J12: 1 | K12: 0 | L12: 0 | M12: 0 | N12: 1 | O12: 0 | P12: 1 | Q12: 0 | R12: 0 | S12: 0 | T12: 0 | U12: 0 | V12: 0 | W12: 0 | X12: 0 | Y12: 1 | Z12: 1 | AA12: =AVERAGE(B12:Z12) -> 0.28
A13: 12 | B13: 0 | C13: 0 | D13: 0 | E13: 0 | F13: 0 | G13: 1 | H13: 0 | I13: 0 | J13: 0 | K13: 0 | L13: 1 | M13: 0 | N13: 1 | O13: 1 | P13: 1 | Q13: 0 | R13: 0 | S13: 0 | T13: 0 | U13: 0 | V13: 1 | W13: 0 | X13: 0 | Y13: 1 | Z13: 0 | AA13: =AVERAGE(B13:Z13) -> 0.28
... A16: 15 | B16: 0 | C16: 1 | D16: 1 | E16: 0 | F16: 0 | G16: 0 | H16: 0 | I16: 0 | J16: 0 | K16: 1 | L16: 1 | M16: 1 | N16: 1 | O16: 0 | P16: 1 | Q16: 1 | R16: 1 | S16: 1 | T16: 1 | U16: 1 | V16: 0 | W16: 1 | X16: 1 | Y16: 1 | Z16: 1 | AA16: =AVERAGE(B16:Z16) -> 0.64

Sheet FR2_Fast
A1: Position | B1: Bertram_T1 | C1: Bertram_T2 | D1: Bertram_T3 | E1: Bertram_T4 | F1: Bertram_T5 | G1: Lasse_T1 | H1: Lasse_T2 | I1: Lasse_T3 | J1: Lasse_T4 | K1: Lasse_T5 | L1: Noah_T1 | M1: Noah_T2 | N1: Noah_T3 | O1: Noah_T4 | P1: Noah_T5 | Q1: Vincent_T1 | R1: Vincent_T2 | S1: Vincent_T3 | T1: Vincent_T4 | U1: Vincent_T5 | V1: Filippa_T1 | W1: Filippa_T2 | X1: Filippa_T3 | Y1: Filippa_T4 | Z1: Filippa_T5 | AA1: Row mean
A2: 1 | B2: 1 | C2: 1 | D2: 1 | E2: 1 | F2: 1 | G2: 0 | H2: 1 | I2: 0 | J2: 0 | K2: 1 | L2: 1 | M2: 1 | N2: 1 | O2: 1 | P2: 0 | Q2: 1 | R2: 1 | S2: 1 | T2: 0 | U2: 0 | V2: 0 | W2: 0 | X2: 0 | Y2: 0 | Z2: 0 | AA2: =AVERAGE(B2:Z2) -> 0.56
A3: 2 | B3: 0 | C3: 1 | D3: 0 | E3: 1 | F3: 0 | G3: 0 | H3: 1 | I3: 0 | J3: 1 | K3: 0 | L3: 1 | M3: 0 | N3: 1 | O3: 1 | P3: 0 | Q3: 1 | R3: 0 | S3: 1 | T3: 0 | U3: 0 | V3: 1 | W3: 0 | X3: 0 | Y3: 0 | Z3: 0 | AA3: =AVERAGE(B3:Z3) -> 0.4
A4: 3 | B4: 1 | C4: 0 | D4: 1 | E4: 0 | F4: 0 | G4: 0 | H4: 0 | I4: 0 | J4: 0 | K4: 0 | L4: 0 | M4: 1 | N4: 0 | O4: 1 | P4: 0 | Q4: 0 | R4: 0 | S4: 0 | T4: 0 | U4: 0 | V4: 0 | W4: 0 | X4: 1 | Y4: 0 | Z4: 0 | AA4: =AVERAGE(B4:Z4) -> 0.2
A5: 4 | B5: 0 | C5: 0 | D5: 0 | E5: 1 | F5: 0 | G5: 1 | H5: 0 | I5: 0 | J5: 1 | K5: 1 | L5: 1 | M5: 0 | N5: 0 | O5: 1 | P5: 0 | Q5: 1 | R5: 1 | S5: 0 | T5: 0 | U5: 0 | V5: 0 | W5: 0 | X5: 0 | Y5: 0 | Z5: 0 | AA5: =AVERAGE(B5:Z5) -> 0.32
A6: 5 | B6: 1 | C6: 0 | D6: 0 | E6: 0 | F6: 0 | G6: 0 | H6: 0 | I6: 0 | J6: 0 | K6: 0 | L6: 0 | M6: 0 | N6: 0 | O6: 0 | P6: 1 | Q6: 0 | R6: 0 | S6: 0 | T6: 0 | U6: 0 | V6: 0 | W6: 0 | X6: 0 | Y6: 0 | Z6: 0 | AA6: =AVERAGE(B6:Z6) -> 0.08
A7: 6 | B7: 0 | C7: 0 | D7: 0 | E7: 1 | F7: 0 | G7: 0 | H7: 0 | I7: 0 | J7: 0 | K7: 0 | L7: 0 | M7: 0 | N7: 0 | O7: 0 | P7: 1 | Q7: 0 | R7: 0 | S7: 0 | T7: 0 | U7: 1 | V7: 0 | W7: 0 | X7: 0 | Y7: 0 | Z7: 0 | AA7: =AVERAGE(B7:Z7) -> 0.12
A8: 7 | B8: 0 | C8: 0 | D8: 0 | E8: 0 | F8: 0 | G8: 0 | H8: 0 | I8: 0 | J8: 0 | K8: 1 | L8: 0 | M8: 0 | N8: 0 | O8: 0 | P8: 0 | Q8: 0 | R8: 0 | S8: 0 | T8: 1 | U8: 0 | V8: 0 | W8: 1 | X8: 0 | Y8: 0 | Z8: 0 | AA8: =AVERAGE(B8:Z8) -> 0.12
A9: 8 | B9: 0 | C9: 0 | D9: 0 | E9: 0 | F9: 0 | G9: 0 | H9: 0 | I9: 1 | J9: 0 | K9: 1 | L9: 0 | M9: 0 | N9: 0 | O9: 1 | P9: 0 | Q9: 1 | R9: 0 | S9: 0 | T9: 0 | U9: 0 | V9: 0 | W9: 0 | X9: 0 | Y9: 1 | Z9: 0 | AA9: =AVERAGE(B9:Z9) -> 0.2
A10: 9 | B10: 0 | C10: 0 | D10: 0 | E10: 0 | F10: 1 | G10: 1 | H10: 0 | I10: 1 | J10: 0 | K10: 0 | L10: 0 | M10: 0 | N10: 0 | O10: 1 | P10: 0 | Q10: 0 | R10: 0 | S10: 0 | T10: 0 | U10: 0 | V10: 0 | W10: 0 | X10: 0 | Y10: 0 | Z10: 0 | AA10: =AVERAGE(B10:Z10) -> 0.16
A11: 10 | B11: 1 | C11: 0 | D11: 0 | E11: 0 | F11: 1 | G11: 0 | H11: 0 | I11: 0 | J11: 0 | K11: 0 | L11: 0 | M11: 0 | N11: 0 | O11: 0 | P11: 0 | Q11: 0 | R11: 0 | S11: 0 | T11: 0 | U11: 0 | V11: 0 | W11: 0 | X11: 0 | Y11: 0 | Z11: 0 | AA11: =AVERAGE(B11:Z11) -> 0.08
A12: 11 | B12: 0 | C12: 0 | D12: 0 | E12: 1 | F12: 0 | G12: 0 | H12: 0 | I12: 0 | J12: 0 | K12: 0 | L12: 0 | M12: 0 | N12: 1 | O12: 0 | P12: 0 | Q12: 0 | R12: 0 | S12: 1 | T12: 0 | U12: 1 | V12: 1 | W12: 0 | X12: 0 | Y12: 1 | Z12: 1 | AA12: =AVERAGE(B12:Z12) -> 0.28
A13: 12 | B13: 1 | C13: 0 | D13: 0 | E13: 0 | F13: 0 | G13: 0 | H13: 1 | I13: 0 | J13: 0 | K13: 0 | L13: 0 | M13: 1 | N13: 0 | O13: 0 | P13: 1 | Q13: 1 | R13: 0 | S13: 1 | T13: 0 | U13: 0 | V13: 0 | W13: 1 | X13: 0 | Y13: 0 | Z13: 0 | AA13: =AVERAGE(B13:Z13) -> 0.28
... A16: 15 | B16: 0 | C16: 0 | D16: 0 | E16: 0 | F16: 0 | G16: 1 | H16: 1 | I16: 1 | J16: 1 | K16: 1 | L16: 0 | M16: 1 | N16: 1 | O16: 0 | P16: 0 | Q16: 0 | R16: 1 | S16: 1 | T16: 1 | U16: 1 | V16: 1 | W16: 1 | X16: 0 | Y16: 1 | Z16: 1 | AA16: =AVERAGE(B16:Z16) -> 0.6

Sheet FR3_FilledDelay
A1: Position | B1: Bertram_T1 | C1: Bertram_T2 | D1: Bertram_T3 | E1: Bertram_T4 | F1: Bertram_T5 | G1: Lasse_T1 | H1: Lasse_T2 | I1: Lasse_T3 | J1: Lasse_T4 | K1: Lasse_T5 | L1: Noah_T1 | M1: Noah_T2 | N1: Noah_T3 | O1: Noah_T4 | P1: Noah_T5 | Q1: Vincent_T1 | R1: Vincent_T2 | S1: Vincent_T3 | T1: Vincent_T4 | U1: Vincent_T5 | V1: Filippa_T1 | W1: Filippa_T2 | X1: Filippa_T3 | Y1: Filippa_T4 | Z1: Filippa_T5 | AA1: Row mean
A2: 1 | B2: 1 | C2: 1 | D2: 0 | E2: 1 | F2: 1 | G2: 0 | H2: 0 | I2: 1 | J2: 0 | K2: 0 | L2: 0 | M2: 1 | N2: 1 | O2: 1 | P2: 1 | Q2: 0 | R2: 1 | S2: 0 | T2: 1 | U2: 0 | V2: 1 | W2: 1 | X2: 0 | Y2: 0 | Z2: 0 | AA2: =AVERAGE(B2:Z2) -> 0.52
A3: 2 | B3: 0 | C3: 1 | D3: 0 | E3: 0 | F3: 1 | G3: 0 | H3: 0 | I3: 0 | J3: 0 | K3: 0 | L3: 1 | M3: 0 | N3: 1 | O3: 1 | P3: 1 | Q3: 1 | R3: 1 | S3: 0 | T3: 0 | U3: 0 | V3: 0 | W3: 0 | X3: 0 | Y3: 0 | Z3: 1 | AA3: =AVERAGE(B3:Z3) -> 0.36
A4: 3 | B4: 1 | C4: 0 | D4: 0 | E4: 0 | F4: 0 | G4: 0 | H4: 1 | I4: 1 | J4: 0 | K4: 0 | L4: 0 | M4: 0 | N4: 1 | O4: 1 | P4: 0 | Q4: 0 | R4: 0 | S4: 0 | T4: 0 | U4: 1 | V4: 0 | W4: 0 | X4: 0 | Y4: 0 | Z4: 0 | AA4: =AVERAGE(B4:Z4) -> 0.24
A5: 4 | B5: 0 | C5: 1 | D5: 0 | E5: 0 | F5: 0 | G5: 0 | H5: 0 | I5: 0 | J5: 0 | K5: 0 | L5: 0 | M5: 0 | N5: 0 | O5: 1 | P5: 1 | Q5: 0 | R5: 1 | S5: 0 | T5: 0 | U5: 0 | V5: 0 | W5: 0 | X5: 0 | Y5: 0 | Z5: 0 | AA5: =AVERAGE(B5:Z5) -> 0.16
A6: 5 | B6: 1 | C6: 0 | D6: 0 | E6: 0 | F6: 0 | G6: 0 | H6: 1 | I6: 1 | J6: 0 | K6: 0 | L6: 0 | M6: 1 | N6: 0 | O6: 0 | P6: 0 | Q6: 0 | R6: 0 | S6: 1 | T6: 0 | U6: 0 | V6: 1 | W6: 0 | X6: 0 | Y6: 0 | Z6: 1 | AA6: =AVERAGE(B6:Z6) -> 0.28
A7: 6 | B7: 0 | C7: 0 | D7: 0 | E7: 0 | F7: 0 | G7: 0 | H7: 0 | I7: 0 | J7: 1 | K7: 0 | L7: 0 | M7: 0 | N7: 0 | O7: 0 | P7: 0 | Q7: 1 | R7: 0 | S7: 0 | T7: 0 | U7: 0 | V7: 0 | W7: 1 | X7: 1 | Y7: 0 | Z7: 0 | AA7: =AVERAGE(B7:Z7) -> 0.16
A8: 7 | B8: 1 | C8: 0 | D8: 1 | E8: 0 | F8: 0 | G8: 0 | H8: 1 | I8: 0 | J8: 0 | K8: 0 | L8: 0 | M8: 0 | N8: 1 | O8: 0 | P8: 1 | Q8: 0 | R8: 1 | S8: 0 | T8: 0 | U8: 0 | V8: 0 | W8: 1 | X8: 0 | Y8: 0 | Z8: 0 | AA8: =AVERAGE(B8:Z8) -> 0.28
A9: 8 | B9: 0 | C9: 0 | D9: 0 | E9: 0 | F9: 0 | G9: 0 | H9: 0 | I9: 0 | J9: 0 | K9: 0 | L9: 0 | M9: 0 | N9: 0 | O9: 0 | P9: 0 | Q9: 1 | R9: 0 | S9: 0 | T9: 1 | U9: 0 | V9: 1 | W9: 0 | X9: 0 | Y9: 1 | Z9: 0 | AA9: =AVERAGE(B9:Z9) -> 0.16
A10: 9 | B10: 0 | C10: 0 | D10: 0 | E10: 0 | F10: 0 | G10: 0 | H10: 0 | I10: 0 | J10: 0 | K10: 0 | L10: 1 | M10: 0 | N10: 1 | O10: 1 | P10: 0 | Q10: 1 | R10: 0 | S10: 0 | T10: 0 | U10: 1 | V10: 0 | W10: 0 | X10: 0 | Y10: 1 | Z10: 0 | AA10: =AVERAGE(B10:Z10) -> 0.24
A11: 10 | B11: 1 | C11: 0 | D11: 0 | E11: 0 | F11: 0 | G11: 0 | H11: 0 | I11: 1 | J11: 0 | K11: 0 | L11: 0 | M11: 0 | N11: 0 | O11: 1 | P11: 1 | Q11: 0 | R11: 0 | S11: 0 | T11: 0 | U11: 0 | V11: 0 | W11: 0 | X11: 0 | Y11: 0 | Z11: 0 | AA11: =AVERAGE(B11:Z11) -> 0.16
A12: 11 | B12: 0 | C12: 1 | D12: 0 | E12: 0 | F12: 0 | G12: 0 | H12: 0 | I12: 0 | J12: 1 | K12: 1 | L12: 0 | M12: 0 | N12: 1 | O12: 0 | P12: 1 | Q12: 0 | R12: 0 | S12: 1 | T12: 0 | U12: 1 | V12: 0 | W12: 0 | X12: 0 | Y12: 0 | Z12: 1 | AA12: =AVERAGE(B12:Z12) -> 0.32
A13: 12 | B13: 1 | C13: 0 | D13: 0 | E13: 0 | F13: 0 | G13: 1 | H13: 0 | I13: 0 | J13: 0 | K13: 0 | L13: 0 | M13: 1 | N13: 0 | O13: 1 | P13: 1 | Q13: 0 | R13: 1 | S13: 1 | T13: 1 | U13: 0 | V13: 0 | W13: 1 | X13: 0 | Y13: 0 | Z13: 0 | AA13: =AVERAGE(B13:Z13) -> 0.36
... A16: 15 | B16: 1 | C16: 0 | D16: 0 | E16: 0 | F16: 1 | G16: 0 | H16: 0 | I16: 0 | J16: 0 | K16: 1 | L16: 0 | M16: 0 | N16: 0 | O16: 0 | P16: 0 | Q16: 1 | R16: 0 | S16: 1 | T16: 1 | U16: 1 | V16: 0 | W16: 0 | X16: 0 | Y16: 1 | Z16: 0 | AA16: =AVERAGE(B16:Z16) -> 0.32

Sheet FR4_EmptyDelay
A1: Position | B1: Bertram_T1 | C1: Bertram_T2 | D1: Bertram_T3 | E1: Bertram_T4 | F1: Bertram_T5 | G1: Lasse_T1 | H1: Lasse_T2 | I1: Lasse_T3 | J1: Lasse_T4 | K1: Lasse_T5 | L1: Noah_T1 | M1: Noah_T2 | N1: Noah_T3 | O1: Noah_T4 | P1: Noah_T5 | Q1: Vincent_T1 | R1: Vincent_T2 | S1: Vincent_T3 | T1: Vincent_T4 | U1: Vincent_T5 | V1: Filippa_T1 | W1: Filippa_T2 | X1: Filippa_T3 | Y1: Filippa_T4 | Z1: Filippa_T5 | AA1: Row mean
A2: 1 | B2: 0 | C2: 1 | D2: 1 | E2: 0 | F2: 0 | G2: 1 | H2: 1 | I2: 1 | J2: 0 | K2: 0 | L2: 0 | M2: 0 | N2: 1 | O2: 0 | P2: 0 | Q2: 1 | R2: 1 | S2: 0 | T2: 1 | U2: 1 | V2: 1 | W2: 0 | X2: 0 | Y2: 1 | Z2: 1 | AA2: =AVERAGE(B2:Z2) -> 0.52
A3: 2 | B3: 0 | C3: 1 | D3: 1 | E3: 0 | F3: 1 | G3: 1 | H3: 1 | I3: 1 | J3: 0 | K3: 0 | L3: 0 | M3: 1 | N3: 0 | O3: 0 | P3: 0 | Q3: 0 | R3: 1 | S3: 0 | T3: 0 | U3: 1 | V3: 0 | W3: 0 | X3: 1 | Y3: 0 | Z3: 0 | AA3: =AVERAGE(B3:Z3) -> 0.4
A4: 3 | B4: 0 | C4: 0 | D4: 1 | E4: 0 | F4: 1 | G4: 1 | H4: 1 | I4: 0 | J4: 1 | K4: 1 | L4: 0 | M4: 0 | N4: 1 | O4: 1 | P4: 0 | Q4: 0 | R4: 1 | S4: 0 | T4: 1 | U4: 0 | V4: 0 | W4: 1 | X4: 0 | Y4: 0 | Z4: 0 | AA4: =AVERAGE(B4:Z4) -> 0.44
A5: 4 | B5: 0 | C5: 0 | D5: 1 | E5: 0 | F5: 1 | G5: 1 | H5: 1 | I5: 1 | J5: 0 | K5: 1 | L5: 0 | M5: 0 | N5: 0 | O5: 0 | P5: 0 | Q5: 1 | R5: 0 | S5: 0 | T5: 0 | U5: 0 | V5: 0 | W5: 0 | X5: 0 | Y5: 0 | Z5: 0 | AA5: =AVERAGE(B5:Z5) -> 0.28
A6: 5 | B6: 1 | C6: 1 | D6: 0 | E6: 0 | F6: 1 | G6: 0 | H6: 1 | I6: 1 | J6: 0 | K6: 0 | L6: 0 | M6: 0 | N6: 0 | O6: 0 | P6: 0 | Q6: 1 | R6: 0 | S6: 0 | T6: 0 | U6: 1 | V6: 0 | W6: 0 | X6: 0 | Y6: 0 | Z6: 1 | AA6: =AVERAGE(B6:Z6) -> 0.32
A7: 6 | B7: 0 | C7: 0 | D7: 1 | E7: 0 | F7: 0 | G7: 0 | H7: 0 | I7: 0 | J7: 1 | K7: 0 | L7: 0 | M7: 0 | N7: 0 | O7: 1 | P7: 0 | Q7: 0 | R7: 0 | S7: 1 | T7: 0 | U7: 0 | V7: 0 | W7: 0 | X7: 0 | Y7: 0 | Z7: 0 | AA7: =AVERAGE(B7:Z7) -> 0.16
A8: 7 | B8: 0 | C8: 0 | D8: 1 | E8: 0 | F8: 0 | G8: 1 | H8: 1 | I8: 0 | J8: 1 | K8: 0 | L8: 1 | M8: 0 | N8: 0 | O8: 0 | P8: 0 | Q8: 0 | R8: 0 | S8: 0 | T8: 0 | U8: 0 | V8: 0 | W8: 0 | X8: 0 | Y8: 1 | Z8: 0 | AA8: =AVERAGE(B8:Z8) -> 0.24
A9: 8 | B9: 0 | C9: 0 | D9: 0 | E9: 1 | F9: 0 | G9: 0 | H9: 0 | I9: 1 | J9: 1 | K9: 0 | L9: 0 | M9: 0 | N9: 1 | O9: 0 | P9: 0 | Q9: 1 | R9: 0 | S9: 0 | T9: 0 | U9: 0 | V9: 0 | W9: 0 | X9: 1 | Y9: 0 | Z9: 0 | AA9: =AVERAGE(B9:Z9) -> 0.24
A10: 9 | B10: 1 | C10: 0 | D10: 0 | E10: 0 | F10: 0 | G10: 1 | H10: 0 | I10: 0 | J10: 1 | K10: 0 | L10: 1 | M10: 0 | N10: 0 | O10: 0 | P10: 0 | Q10: 0 | R10: 0 | S10: 0 | T10: 0 | U10: 0 | V10: 0 | W10: 0 | X10: 0 | Y10: 0 | Z10: 0 | AA10: =AVERAGE(B10:Z10) -> 0.16
A11: 10 | B11: 1 | C11: 0 | D11: 0 | E11: 1 | F11: 0 | G11: 0 | H11: 0 | I11: 0 | J11: 0 | K11: 0 | L11: 0 | M11: 1 | N11: 0 | O11: 0 | P11: 1 | Q11: 0 | R11: 0 | S11: 0 | T11: 0 | U11: 0 | V11: 0 | W11: 0 | X11: 0 | Y11: 0 | Z11: 0 | AA11: =AVERAGE(B11:Z11) -> 0.16
A12: 11 | B12: 0 | C12: 0 | D12: 0 | E12: 0 | F12: 1 | G12: 0 | H12: 0 | I12: 0 | J12: 0 | K12: 0 | L12: 0 | M12: 1 | N12: 0 | O12: 1 | P12: 1 | Q12: 0 | R12: 0 | S12: 0 | T12: 0 | U12: 0 | V12: 1 | W12: 0 | X12: 0 | Y12: 0 | Z12: 0 | AA12: =AVERAGE(B12:Z12) -> 0.2
A13: 12 | B13: 0 | C13: 0 | D13: 0 | E13: 1 | F13: 0 | G13: 1 | H13: 0 | I13: 0 | J13: 0 | K13: 0 | L13: 1 | M13: 0 | N13: 0 | O13: 0 | P13: 1 | Q13: 0 | R13: 0 | S13: 0 | T13: 1 | U13: 0 | V13: 0 | W13: 1 | X13: 0 | Y13: 1 | Z13: 0 | AA13: =AVERAGE(B13:Z13) -> 0.28
... A16: 15 | B16: 0 | C16: 1 | D16: 0 | E16: 1 | F16: 0 | G16: 0 | H16: 0 | I16: 0 | J16: 0 | K16: 0 | L16: 1 | M16: 1 | N16: 1 | O16: 1 | P16: 1 | Q16: 1 | R16: 1 | S16: 1 | T16: 1 | U16: 1 | V16: 0 | W16: 0 | X16: 1 | Y16: 1 | Z16: 0 | AA16: =AVERAGE(B16:Z16) -> 0.56

Sheet SR1_Control
A1: Position | B1: Bertram_T1 | C1: Bertram_T2 | D1: Bertram_T3 | E1: Bertram_T4 | F1: Bertram_T5 | G1: Lasse_T1 | H1: Lasse_T2 | I1: Lasse_T3 | J1: Lasse_T4 | K1: Lasse_T5 | L1: Noah_T1 | M1: Noah_T2 | N1: Noah_T3 | O1: Noah_T4 | P1: Noah_T5 | Q1: Vincent_T1 | R1: Vincent_T2 | S1: Vincent_T3 | T1: Vincent_T4 | U1: Vincent_T5 | V1: Filippa_T1 | W1: Filippa_T2 | X1: Filippa_T3 | Y1: Filippa_T4 | Z1: Filippa_T5 | AA1: Row mean
A2: 1 | B2: 1 | C2: 1 | D2: 1 | E2: 1 | F2: 1 | G2: 1 | H2: 1 | I2: 1 | J2: 1 | K2: 1 | L2: 1 | M2: 1 | N2: 1 | O2: 1 | P2: 1 | Q2: 1 | R2: 1 | S2: 1 | T2: 1 | U2: 1 | V2: 1 | W2: 1 | X2: 1 | Y2: 1 | Z2: 1 | AA2: =AVERAGE(B2:Z2) -> 1
A3: 2 | B3: 0 | C3: 1 | D3: 1 | E3: 0 | F3: 1 | G3: 1 | H3: 1 | I3: 1 | J3: 1 | K3: 0 | L3: 1 | M3: 1 | N3: 1 | O3: 1 | P3: 1 | Q3: 1 | R3: 1 | S3: 1 | T3: 1 | U3: 1 | V3: 1 | W3: 1 | X3: 1 | Y3: 1 | Z3: 1 | AA3: =AVERAGE(B3:Z3) -> 0.88
A4: 3 | B4: 0 | C4: 1 | D4: 0 | E4: 0 | F4: 0 | G4: 1 | H4: 1 | I4: 1 | J4: 0 | K4: 0 | L4: 1 | M4: 1 | N4: 1 | O4: 1 | P4: 1 | Q4: 1 | R4: 1 | S4: 1 | T4: 1 | U4: 1 | V4: 0 | W4: 1 | X4: 1 | Y4: 1 | Z4: 1 | AA4: =AVERAGE(B4:Z4) -> 0.72
A5: 4 | B5: 0 | C5: 1 | D5: 0 | E5: 0 | F5: 1 | G5: 1 | H5: 0 | I5: 0 | J5: 0 | K5: 0 | L5: 1 | M5: 1 | N5: 1 | O5: 1 | P5: 1 | Q5: 1 | R5: 0 | S5: 1 | T5: 1 | U5: 1 | V5: 0 | W5: 1 | X5: 1 | Y5: 0 | Z5: 1 | AA5: =AVERAGE(B5:Z5) -> 0.6
A6: 5 | B6: 0 | C6: 0 | D6: 0 | E6: 0 | F6: 0 | G6: 0 | H6: 1 | I6: 0 | J6: 0 | K6: 0 | L6: 1 | M6: 1 | N6: 1 | O6: 1 | P6: 1 | Q6: 1 | R6: 1 | S6: 1 | T6: 0 | U6: 1 | V6: 1 | W6: 1 | X6: 0 | Y6: 0 | Z6: 0 | AA6: =AVERAGE(B6:Z6) -> 0.48
A7: 6 | B7: 0 | C7: 0 | D7: 0 | E7: 0 | F7: 1 | G7: 1 | H7: 0 | I7: 1 | J7: 1 | K7: 0 | L7: 0 | M7: 1 | N7: 1 | O7: 1 | P7: 1 | Q7: 1 | R7: 1 | S7: 1 | T7: 1 | U7: 0 | V7: 1 | W7: 0 | X7: 0 | Y7: 0 | Z7: 0 | AA7: =AVERAGE(B7:Z7) -> 0.52
A8: 7 | B8: 0 | C8: 0 | D8: 1 | E8: 0 | F8: 0 | G8: 1 | H8: 0 | I8: 0 | J8: 1 | K8: 0 | L8: 0 | M8: 1 | N8: 0 | O8: 1 | P8: 1 | Q8: 0 | R8: 1 | S8: 1 | T8: 1 | U8: 0 | V8: 0 | W8: 0 | X8: 0 | Y8: 0 | Z8: 1 | AA8: =AVERAGE(B8:Z8) -> 0.4
A9: 8 | B9: 0 | C9: 0 | D9: 0 | E9: 1 | F9: 0 | G9: 1 | H9: 0 | I9: 0 | J9: 0 | K9: 0 | L9: 0 | M9: 0 | N9: 0 | O9: 0 | P9: 1 | Q9: 0 | R9: 0 | S9: 1 | T9: 0 | U9: 0 | V9: 0 | W9: 0 | X9: 1 | Y9: 0 | Z9: 0 | AA9: =AVERAGE(B9:Z9) -> 0.2
A10: 9 | B10: 0 | C10: 0 | D10: 0 | E10: 0 | F10: 0 | G10: 0 | H10: 0 | I10: 0 | J10: 0 | K10: 1 | L10: 0 | M10: 0 | N10: 0 | O10: 0 | P10: 0 | Q10: 1 | R10: 0 | S10: 0 | T10: 0 | U10: 0 | V10: 0 | W10: 0 | X10: 0 | Y10: 0 | Z10: 0 | AA10: =AVERAGE(B10:Z10) -> 0.08
A11: 10 | B11: 0 | C11: 0 | D11: 0 | E11: 0 | F11: 1 | G11: 0 | H11: 0 | I11: 1 | J11: 0 | K11: 1 | L11: 0 | M11: 0 | N11: 0 | O11: 0 | P11: 0 | Q11: 0 | R11: 0 | S11: 0 | T11: 0 | U11: 0 | V11: 0 | W11: 0 | X11: 0 | Y11: 0 | Z11: 0 | AA11: =AVERAGE(B11:Z11) -> 0.12

Sheet SR2_Chunking
A1: Position | B1: Bertram_T1 | C1: Bertram_T2 | D1: Bertram_T3 | E1: Bertram_T4 | F1: Bertram_T5 | G1: Lasse_T1 | H1: Lasse_T2 | I1: Lasse_T3 | J1: Lasse_T4 | K1: Lasse_T5 | L1: Noah_T1 | M1: Noah_T2 | N1: Noah_T3 | O1: Noah_T4 | P1: Noah_T5 | Q1: Vincent_T1 | R1: Vincent_T2 | S1: Vincent_T3 | T1: Vincent_T4 | U1: Vincent_T5 | V1: Filippa_T1 | W1: Filippa_T2 | X1: Filippa_T3 | Y1: Filippa_T4 | Z1: Filippa_T5 | AA1: Row mean
A2: 1 | B2: 1 | C2: 1 | D2: 1 | E2: 1 | F2: 1 | G2: 1 | H2: 1 | I2: 1 | J2: 1 | K2: 0 | L2: 1 | M2: 1 | N2: 1 | O2: 1 | P2: 1 | Q2: 1 | R2: 1 | S2: 1 | T2: 1 | U2: 1 | V2: 1 | W2: 1 | X2: 1 | Y2: 1 | Z2: 1 | AA2: =AVERAGE(B2:Z2) -> 0.96
A3: 2 | B3: 1 | C3: 1 | D3: 1 | E3: 0 | F3: 1 | G3: 1 | H3: 1 | I3: 1 | J3: 0 | K3: 0 | L3: 1 | M3: 1 | N3: 1 | O3: 1 | P3: 1 | Q3: 1 | R3: 1 | S3: 1 | T3: 1 | U3: 1 | V3: 1 | W3: 1 | X3: 0 | Y3: 1 | Z3: 1 | AA3: =AVERAGE(B3:Z3) -> 0.84
A4: 3 | B4: 1 | C4: 1 | D4: 1 | E4: 0 | F4: 1 | G4: 1 | H4: 1 | I4: 1 | J4: 0 | K4: 0 | L4: 1 | M4: 1 | N4: 1 | O4: 1 | P4: 1 | Q4: 1 | R4: 1 | S4: 1 | T4: 1 | U4: 1 | V4: 1 | W4: 1 | X4: 1 | Y4: 1 | Z4: 0 | AA4: =AVERAGE(B4:Z4) -> 0.84
A5: 4 | B5: 0 | C5: 1 | D5: 0 | E5: 0 | F5: 1 | G5: 0 | H5: 1 | I5: 1 | J5: 0 | K5: 1 | L5: 1 | M5: 1 | N5: 1 | O5: 1 | P5: 1 | Q5: 1 | R5: 1 | S5: 1 | T5: 1 | U5: 1 | V5: 1 | W5: 1 | X5: 0 | Y5: 1 | Z5: 1 | AA5: =AVERAGE(B5:Z5) -> 0.76
A6: 5 | B6: 1 | C6: 1 | D6: 1 | E6: 0 | F6: 1 | G6: 0 | H6: 1 | I6: 1 | J6: 0 | K6: 1 | L6: 1 | M6: 1 | N6: 1 | O6: 1 | P6: 1 | Q6: 1 | R6: 1 | S6: 1 | T6: 1 | U6: 0 | V6: 1 | W6: 1 | X6: 0 | Y6: 1 | Z6: 1 | AA6: =AVERAGE(B6:Z6) -> 0.8
A7: 6 | B7: 0 | C7: 1 | D7: 0 | E7: 1 | F7: 1 | G7: 1 | H7: 0 | I7: 0 | J7: 1 | K7: 0 | L7: 0 | M7: 1 | N7: 1 | O7: 1 | P7: 1 | Q7: 1 | R7: 1 | S7: 1 | T7: 1 | U7: 1 | V7: 0 | W7: 1 | X7: 0 | Y7: 1 | Z7: 1 | AA7: =AVERAGE(B7:Z7) -> 0.68
A8: 7 | B8: 1 | C8: 1 | D8: 0 | E8: 1 | F8: 0 | G8: 0 | H8: 0 | I8: 0 | J8: 1 | K8: 0 | L8: 0 | M8: 1 | N8: 1 | O8: 1 | P8: 1 | Q8: 1 | R8: 1 | S8: 1 | T8: 1 | U8: 1 | V8: 0 | W8: 0 | X8: 0 | Y8: 1 | Z8: 1 | AA8: =AVERAGE(B8:Z8) -> 0.6
A9: 8 | B9: 1 | C9: 1 | D9: 0 | E9: 1 | F9: 1 | G9: 1 | H9: 0 | I9: 0 | J9: 1 | K9: 1 | L9: 0 | M9: 1 | N9: 1 | O9: 1 | P9: 1 | Q9: 0 | R9: 0 | S9: 1 | T9: 1 | U9: 1 | V9: 0 | W9: 0 | X9: 0 | Y9: 1 | Z9: 1 | AA9: =AVERAGE(B9:Z9) -> 0.64
A10: 9 | B10: 1 | C10: 1 | D10: 0 | E10: 1 | F10: 0 | G10: 1 | H10: 1 | I10: 0 | J10: 1 | K10: 1 | L10: 0 | M10: 1 | N10: 1 | O10: 1 | P10: 1 | Q10: 0 | R10: 1 | S10: 1 | T10: 1 | U10: 1 | V10: 0 | W10: 0 | X10: 0 | Y10: 1 | Z10: 1 | AA10: =AVERAGE(B10:Z10) -> 0.68
A11: 10 | B11: 1 | C11: 0 | D11: 0 | E11: 0 | F11: 0 | G11: 0 | H11: 1 | I11: 0 | J11: 1 | K11: 1 | L11: 0 | M11: 1 | N11: 1 | O11: 1 | P11: 1 | Q11: 0 | R11: 1 | S11: 1 | T11: 1 | U11: 0 | V11: 0 | W11: 0 | X11: 0 | Y11: 0 | Z11: 0 | AA11: =AVERAGE(B11:Z11) -> 0.44

Sheet SR3_Suppression
A1: Position | B1: Bertram_T1 | C1: Bertram_T2 | D1: Bertram_T3 | E1: Bertram_T4 | F1: Bertram_T5 | G1: Lasse_T1 | H1: Lasse_T2 | I1: Lasse_T3 | J1: Lasse_T4 | K1: Lasse_T5 | L1: Noah_T1 | M1: Noah_T2 | N1: Noah_T3 | O1: Noah_T4 | P1: Noah_T5 | Q1: Vincent_T1 | R1: Vincent_T2 | S1: Vincent_T3 | T1: Vincent_T4 | U1: Vincent_T5 | V1: Filippa_T1 | W1: Filippa_T2 | X1: Filippa_T3 | Y1: Filippa_T4 | Z1: Filippa_T5 | AA1: Row mean
A2: 1 | B2: 1 | C2: 0 | D2: 0 | E2: 0 | F2: 0 | G2: 0 | H2: 1 | I2: 0 | J2: 0 | K2: 0 | L2: 1 | M2: 1 | N2: 1 | O2: 1 | P2: 1 | Q2: 1 | R2: 1 | S2: 1 | T2: 1 | U2: 1 | V2: 1 | W2: 1 | X2: 1 | Y2: 1 | Z2: 1 | AA2: =AVERAGE(B2:Z2) -> 0.68
A3: 2 | B3: 1 | C3: 1 | D3: 0 | E3: 1 | F3: 0 | G3: 0 | H3: 1 | I3: 0 | J3: 1 | K3: 1 | L3: 1 | M3: 1 | N3: 1 | O3: 1 | P3: 1 | Q3: 1 | R3: 1 | S3: 1 | T3: 1 | U3: 1 | V3: 1 | W3: 0 | X3: 1 | Y3: 0 | Z3: 1 | AA3: =AVERAGE(B3:Z3) -> 0.76
A4: 3 | B4: 0 | C4: 1 | D4: 0 | E4: 1 | F4: 0 | G4: 0 | H4: 0 | I4: 1 | J4: 1 | K4: 1 | L4: 1 | M4: 1 | N4: 1 | O4: 1 | P4: 0 | Q4: 1 | R4: 1 | S4: 1 | T4: 0 | U4: 1 | V4: 0 | W4: 1 | X4: 1 | Y4: 0 | Z4: 1 | AA4: =AVERAGE(B4:Z4) -> 0.64
A5: 4 | B5: 1 | C5: 1 | D5: 1 | E5: 0 | F5: 0 | G5: 0 | H5: 1 | I5: 1 | J5: 0 | K5: 1 | L5: 0 | M5: 1 | N5: 0 | O5: 1 | P5: 1 | Q5: 1 | R5: 0 | S5: 1 | T5: 0 | U5: 0 | V5: 0 | W5: 1 | X5: 0 | Y5: 1 | Z5: 0 | AA5: =AVERAGE(B5:Z5) -> 0.52
A6: 5 | B6: 0 | C6: 0 | D6: 1 | E6: 1 | F6: 1 | G6: 0 | H6: 0 | I6: 0 | J6: 0 | K6: 0 | L6: 0 | M6: 0 | N6: 0 | O6: 0 | P6: 1 | Q6: 0 | R6: 0 | S6: 0 | T6: 0 | U6: 0 | V6: 0 | W6: 0 | X6: 0 | Y6: 0 | Z6: 1 | AA6: =AVERAGE(B6:Z6) -> 0.2
A7: 6 | B7: 1 | C7: 0 | D7: 0 | E7: 1 | F7: 1 | G7: 0 | H7: 0 | I7: 0 | J7: 0 | K7: 1 | L7: 0 | M7: 0 | N7: 0 | O7: 0 | P7: 0 | Q7: 1 | R7: 0 | S7: 0 | T7: 0 | U7: 0 | V7: 0 | W7: 0 | X7: 0 | Y7: 0 | Z7: 0 | AA7: =AVERAGE(B7:Z7) -> 0.2
A8: 7 | B8: 0 | C8: 1 | D8: 0 | E8: 0 | F8: 1 | G8: 1 | H8: 1 | I8: 0 | J8: 1 | K8: 0 | L8: 0 | M8: 0 | N8: 0 | O8: 0 | P8: 0 | Q8: 0 | R8: 0 | S8: 0 | T8: 1 | U8: 0 | V8: 0 | W8: 0 | X8: 0 | Y8: 0 | Z8: 0 | AA8: =AVERAGE(B8:Z8) -> 0.24
A9: 8 | B9: 0 | C9: 0 | D9: 0 | E9: 0 | F9: 0 | G9: 1 | H9: 0 | I9: 1 | J9: 0 | K9: 0 | L9: 0 | M9: 0 | N9: 0 | O9: 0 | P9: 0 | Q9: 0 | R9: 0 | S9: 0 | T9: 0 | U9: 0 | V9: 0 | W9: 0 | X9: 1 | Y9: 0 | Z9: 0 | AA9: =AVERAGE(B9:Z9) -> 0.12
A10: 9 | B10: 0 | C10: 0 | D10: 1 | E10: 0 | F10: 0 | G10: 0 | H10: 0 | I10: 1 | J10: 0 | K10: 0 | L10: 0 | M10: 0 | N10: 0 | O10: 0 | P10: 0 | Q10: 0 | R10: 1 | S10: 0 | T10: 0 | U10: 0 | V10: 0 | W10: 0 | X10: 0 | Y10: 0 | Z10: 0 | AA10: =AVERAGE(B10:Z10) -> 0.12
A11: 10 | B11: 0 | C11: 0 | D11: 1 | E11: 0 | F11: 0 | G11: 0 | H11: 0 | I11: 1 | J11: 0 | K11: 0 | L11: 0 | M11: 0 | N11: 0 | O11: 0 | P11: 0 | Q11: 0 | R11: 0 | S11: 0 | T11: 0 | U11: 0 | V11: 0 | W11: 0 | X11: 0 | Y11: 1 | Z11: 0 | AA11: =AVERAGE(B11:Z11) -> 0.12

Sheet SR4_Tapping
A1: Position | B1: Bertram_T1 | C1: Bertram_T2 | D1: Bertram_T3 | E1: Bertram_T4 | F1: Bertram_T5 | G1: Lasse_T1 | H1: Lasse_T2 | I1: Lasse_T3 | J1: Lasse_T4 | K1: Lasse_T5 | L1: Noah_T1 | M1: Noah_T2 | N1: Noah_T3 | O1: Noah_T4 | P1: Noah_T5 | Q1: Vincent_T1 | R1: Vincent_T2 | S1: Vincent_T3 | T1: Vincent_T4 | U1: Vincent_T5 | V1: Filippa_T1 | W1: Filippa_T2 | X1: Filippa_T3 | Y1: Filippa_T4 | Z1: Filippa_T5 | AA1: Row mean
A2: 1 | B2: 1 | C2: 1 | D2: 1 | E2: 0 | F2: 0 | G2: 0 | H2: 1 | I2: 0 | J2: 1 | K2: 1 | L2: 1 | M2: 1 | N2: 1 | O2: 1 | P2: 1 | Q2: 1 | R2: 1 | S2: 1 | T2: 1 | U2: 1 | V2: 1 | W2: 0 | X2: 1 | Y2: 1 | Z2: 1 | AA2: =AVERAGE(B2:Z2) -> 0.8
A3: 2 | B3: 1 | C3: 0 | D3: 1 | E3: 1 | F3: 1 | G3: 0 | H3: 1 | I3: 0 | J3: 1 | K3: 0 | L3: 1 | M3: 1 | N3: 1 | O3: 1 | P3: 1 | Q3: 1 | R3: 1 | S3: 1 | T3: 1 | U3: 1 | V3: 0 | W3: 0 | X3: 1 | Y3: 1 | Z3: 1 | AA3: =AVERAGE(B3:Z3) -> 0.76
A4: 3 | B4: 0 | C4: 1 | D4: 0 | E4: 0 | F4: 1 | G4: 0 | H4: 1 | I4: 0 | J4: 0 | K4: 0 | L4: 1 | M4: 1 | N4: 1 | O4: 1 | P4: 1 | Q4: 1 | R4: 1 | S4: 1 | T4: 1 | U4: 1 | V4: 0 | W4: 1 | X4: 0 | Y4: 1 | Z4: 0 | AA4: =AVERAGE(B4:Z4) -> 0.6
A5: 4 | B5: 1 | C5: 1 | D5: 1 | E5: 1 | F5: 0 | G5: 0 | H5: 1 | I5: 1 | J5: 0 | K5: 0 | L5: 1 | M5: 1 | N5: 1 | O5: 0 | P5: 1 | Q5: 1 | R5: 0 | S5: 1 | T5: 1 | U5: 1 | V5: 0 | W5: 0 | X5: 0 | Y5: 0 | Z5: 0 | AA5: =AVERAGE(B5:Z5) -> 0.56
A6: 5 | B6: 1 | C6: 0 | D6: 0 | E6: 0 | F6: 0 | G6: 0 | H6: 1 | I6: 0 | J6: 1 | K6: 0 | L6: 1 | M6: 1 | N6: 1 | O6: 0 | P6: 1 | Q6: 1 | R6: 0 | S6: 1 | T6: 1 | U6: 1 | V6: 0 | W6: 1 | X6: 0 | Y6: 0 | Z6: 1 | AA6: =AVERAGE(B6:Z6) -> 0.52
A7: 6 | B7: 0 | C7: 1 | D7: 1 | E7: 0 | F7: 1 | G7: 0 | H7: 0 | I7: 0 | J7: 1 | K7: 0 | L7: 0 | M7: 1 | N7: 1 | O7: 0 | P7: 0 | Q7: 0 | R7: 0 | S7: 1 | T7: 1 | U7: 0 | V7: 0 | W7: 1 | X7: 0 | Y7: 0 | Z7: 0 | AA7: =AVERAGE(B7:Z7) -> 0.36
A8: 7 | B8: 0 | C8: 1 | D8: 0 | E8: 1 | F8: 0 | G8: 0 | H8: 0 | I8: 0 | J8: 0 | K8: 1 | L8: 0 | M8: 1 | N8: 1 | O8: 0 | P8: 0 | Q8: 0 | R8: 0 | S8: 1 | T8: 0 | U8: 0 | V8: 1 | W8: 0 | X8: 0 | Y8: 1 | Z8: 0 | AA8: =AVERAGE(B8:Z8) -> 0.32
A9: 8 | B9: 0 | C9: 0 | D9: 0 | E9: 0 | F9: 0 | G9: 1 | H9: 0 | I9: 1 | J9: 0 | K9: 0 | L9: 0 | M9: 0 | N9: 0 | O9: 0 | P9: 0 | Q9: 0 | R9: 0 | S9: 0 | T9: 0 | U9: 0 | V9: 0 | W9: 1 | X9: 1 | Y9: 0 | Z9: 0 | AA9: =AVERAGE(B9:Z9) -> 0.16
A10: 9 | B10: 0 | C10: 0 | D10: 0 | E10: 0 | F10: 0 | G10: 1 | H10: 0 | I10: 1 | J10: 0 | K10: 1 | L10: 0 | M10: 0 | N10: 0 | O10: 0 | P10: 0 | Q10: 1 | R10: 0 | S10: 0 | T10: 0 | U10: 0 | V10: 0 | W10: 0 | X10: 0 | Y10: 0 | Z10: 1 | AA10: =AVERAGE(B10:Z10) -> 0.2
A11: 10 | B11: 1 | C11: 0 | D11: 0 | E11: 1 | F11: 1 | G11: 1 | H11: 0 | I11: 1 | J11: 1 | K11: 1 | L11: 0 | M11: 0 | N11: 0 | O11: 0 | P11: 0 | Q11: 0 | R11: 1 | S11: 0 | T11: 0 | U11: 0 | V11: 1 | W11: 0 | X11: 0 | Y11: 0 | Z11: 0 | AA11: =AVERAGE(B11:Z11) -> 0.36

Sheet FR_PositionMeans
A1: Position | B1: FR1_Control | C1: FR2_Fast | D1: FR3_FilledDelay | E1: FR4_EmptyDelay
A2: 1 | B2: =FR1_Control!AA2 -> 0.64 | C2: =FR2_Fast!AA2 -> 0.56 | D2: =FR3_FilledDelay!AA2 -> 0.52 | E2: =FR4_EmptyDelay!AA2 -> 0.52
A3: 2 | B3: =FR1_Control!AA3 -> 0.52 | C3: =FR2_Fast!AA3 -> 0.4 | D3: =FR3_FilledDelay!AA3 -> 0.36 | E3: =FR4_EmptyDelay!AA3 -> 0.4
A4: 3 | B4: =FR1_Control!AA4 -> 0.6 | C4: =FR2_Fast!AA4 -> 0.2 | D4: =FR3_FilledDelay!AA4 -> 0.24 | E4: =FR4_EmptyDelay!AA4 -> 0.44
A5: 4 | B5: =FR1_Control!AA5 -> 0.44 | C5: =FR2_Fast!AA5 -> 0.32 | D5: =FR3_FilledDelay!AA5 -> 0.16 | E5: =FR4_EmptyDelay!AA5 -> 0.28
A6: 5 | B6: =FR1_Control!AA6 -> 0.44 | C6: =FR2_Fast!AA6 -> 0.08 | D6: =FR3_FilledDelay!AA6 -> 0.28 | E6: =FR4_EmptyDelay!AA6 -> 0.32
A7: 6 | B7: =FR1_Control!AA7 -> 0.32 | C7: =FR2_Fast!AA7 -> 0.12 | D7: =FR3_FilledDelay!AA7 -> 0.16 | E7: =FR4_EmptyDelay!AA7 -> 0.16
A8: 7 | B8: =FR1_Control!AA8 -> 0.28 | C8: =FR2_Fast!AA8 -> 0.12 | D8: =FR3_FilledDelay!AA8 -> 0.28 | E8: =FR4_EmptyDelay!AA8 -> 0.24
A9: 8 | B9: =FR1_Control!AA9 -> 0.24 | C9: =FR2_Fast!AA9 -> 0.2 | D9: =FR3_FilledDelay!AA9 -> 0.16 | E9: =FR4_EmptyDelay!AA9 -> 0.24
A10: 9 | B10: =FR1_Control!AA10 -> 0.36 | C10: =FR2_Fast!AA10 -> 0.16 | D10: =FR3_FilledDelay!AA10 -> 0.24 | E10: =FR4_EmptyDelay!AA10 -> 0.16
A11: 10 | B11: =FR1_Control!AA11 -> 0.4 | C11: =FR2_Fast!AA11 -> 0.08 | D11: =FR3_FilledDelay!AA11 -> 0.16 | E11: =FR4_EmptyDelay!AA11 -> 0.16
A12: 11 | B12: =FR1_Control!AA12 -> 0.28 | C12: =FR2_Fast!AA12 -> 0.28 | D12: =FR3_FilledDelay!AA12 -> 0.32 | E12: =FR4_EmptyDelay!AA12 -> 0.2
A13: 12 | B13: =FR1_Control!AA13 -> 0.28 | C13: =FR2_Fast!AA13 -> 0.28 | D13: =FR3_FilledDelay!AA13 -> 0.36 | E13: =FR4_EmptyDelay!AA13 -> 0.28
... A16: 15 | B16: =FR1_Control!AA16 -> 0.64 | C16: =FR2_Fast!AA16 -> 0.6 | D16: =FR3_FilledDelay!AA16 -> 0.32 | E16: =FR4_EmptyDelay!AA16 -> 0.56
A17: All positions | B17: =AVERAGE(B2:B16) -> 0.42133333 | C17: =AVERAGE(C2:C16) -> 0.27733333 | D17: =AVERAGE(D2:D16) -> 0.264 | E17: =AVERAGE(E2:E16) -> 0.31466667

Sheet FR_TrialScores
A1: Trial ID | B1: Participant | C1: Trial | D1: FR1_Control | E1: FR2_Fast | F1: FR3_FilledDelay | G1: FR4_EmptyDelay
A2: Bertram_T1 | B2: Bertram | C2: 1 | D2: =AVERAGE(FR1_Control!B2:B16) -> 0.53333333 | E2: =AVERAGE(FR2_Fast!B2:B16) -> 0.33333333 | F2: =AVERAGE(FR3_FilledDelay!B2:B16) -> 0.46666667 | G2: =AVERAGE(FR4_EmptyDelay!B2:B16) -> 0.26666667
A3: Bertram_T2 | B3: Bertram | C3: 2 | D3: =AVERAGE(FR1_Control!C2:C16) -> 0.4 | E3: =AVERAGE(FR2_Fast!C2:C16) -> 0.13333333 | F3: =AVERAGE(FR3_FilledDelay!C2:C16) -> 0.26666667 | G3: =AVERAGE(FR4_EmptyDelay!C2:C16) -> 0.26666667
A4: Bertram_T3 | B4: Bertram | C4: 3 | D4: =AVERAGE(FR1_Control!D2:D16) -> 0.26666667 | E4: =AVERAGE(FR2_Fast!D2:D16) -> 0.26666667 | F4: =AVERAGE(FR3_FilledDelay!D2:D16) -> 0.066666667 | G4: =AVERAGE(FR4_EmptyDelay!D2:D16) -> 0.4
A5: Bertram_T4 | B5: Bertram | C5: 4 | D5: =AVERAGE(FR1_Control!E2:E16) -> 0.26666667 | E5: =AVERAGE(FR2_Fast!E2:E16) -> 0.33333333 | F5: =AVERAGE(FR3_FilledDelay!E2:E16) -> 0.066666667 | G5: =AVERAGE(FR4_EmptyDelay!E2:E16) -> 0.26666667
A6: Bertram_T5 | B6: Bertram | C6: 5 | D6: =AVERAGE(FR1_Control!F2:F16) -> 0.2 | E6: =AVERAGE(FR2_Fast!F2:F16) -> 0.2 | F6: =AVERAGE(FR3_FilledDelay!F2:F16) -> 0.2 | G6: =AVERAGE(FR4_EmptyDelay!F2:F16) -> 0.4
A7: Lasse_T1 | B7: Lasse | C7: 1 | D7: =AVERAGE(FR1_Control!G2:G16) -> 0.46666667 | E7: =AVERAGE(FR2_Fast!G2:G16) -> 0.2 | F7: =AVERAGE(FR3_FilledDelay!G2:G16) -> 0.13333333 | G7: =AVERAGE(FR4_EmptyDelay!G2:G16) -> 0.46666667
A8: Lasse_T2 | B8: Lasse | C8: 2 | D8: =AVERAGE(FR1_Control!H2:H16) -> 0.26666667 | E8: =AVERAGE(FR2_Fast!H2:H16) -> 0.4 | F8: =AVERAGE(FR3_FilledDelay!H2:H16) -> 0.2 | G8: =AVERAGE(FR4_EmptyDelay!H2:H16) -> 0.4
A9: Lasse_T3 | B9: Lasse | C9: 3 | D9: =AVERAGE(FR1_Control!I2:I16) -> 0.26666667 | E9: =AVERAGE(FR2_Fast!I2:I16) -> 0.2 | F9: =AVERAGE(FR3_FilledDelay!I2:I16) -> 0.26666667 | G9: =AVERAGE(FR4_EmptyDelay!I2:I16) -> 0.4
A10: Lasse_T4 | B10: Lasse | C10: 4 | D10: =AVERAGE(FR1_Control!J2:J16) -> 0.4 | E10: =AVERAGE(FR2_Fast!J2:J16) -> 0.33333333 | F10: =AVERAGE(FR3_FilledDelay!J2:J16) -> 0.2 | G10: =AVERAGE(FR4_EmptyDelay!J2:J16) -> 0.33333333
A11: Lasse_T5 | B11: Lasse | C11: 5 | D11: =AVERAGE(FR1_Control!K2:K16) -> 0.46666667 | E11: =AVERAGE(FR2_Fast!K2:K16) -> 0.46666667 | F11: =AVERAGE(FR3_FilledDelay!K2:K16) -> 0.2 | G11: =AVERAGE(FR4_EmptyDelay!K2:K16) -> 0.26666667
A12: Noah_T1 | B12: Noah | C12: 1 | D12: =AVERAGE(FR1_Control!L2:L16) -> 0.4 | E12: =AVERAGE(FR2_Fast!L2:L16) -> 0.26666667 | F12: =AVERAGE(FR3_FilledDelay!L2:L16) -> 0.13333333 | G12: =AVERAGE(FR4_EmptyDelay!L2:L16) -> 0.33333333
A13: Noah_T2 | B13: Noah | C13: 2 | D13: =AVERAGE(FR1_Control!M2:M16) -> 0.4 | E13: =AVERAGE(FR2_Fast!M2:M16) -> 0.26666667 | F13: =AVERAGE(FR3_FilledDelay!M2:M16) -> 0.2 | G13: =AVERAGE(FR4_EmptyDelay!M2:M16) -> 0.33333333
A14: Noah_T3 | B14: Noah | C14: 3 | D14: =AVERAGE(FR1_Control!N2:N16) -> 0.46666667 | E14: =AVERAGE(FR2_Fast!N2:N16) -> 0.33333333 | F14: =AVERAGE(FR3_FilledDelay!N2:N16) -> 0.4 | G14: =AVERAGE(FR4_EmptyDelay!N2:N16) -> 0.4
A15: Noah_T4 | B15: Noah | C15: 4 | D15: =AVERAGE(FR1_Control!O2:O16) -> 0.6 | E15: =AVERAGE(FR2_Fast!O2:O16) -> 0.46666667 | F15: =AVERAGE(FR3_FilledDelay!O2:O16) -> 0.46666667 | G15: =AVERAGE(FR4_EmptyDelay!O2:O16) -> 0.33333333
A16: Noah_T5 | B16: Noah | C16: 5 | D16: =AVERAGE(FR1_Control!P2:P16) -> 0.46666667 | E16: =AVERAGE(FR2_Fast!P2:P16) -> 0.2 | F16: =AVERAGE(FR3_FilledDelay!P2:P16) -> 0.46666667 | G16: =AVERAGE(FR4_EmptyDelay!P2:P16) -> 0.4
A17: Vincent_T1 | B17: Vincent | C17: 1 | D17: =AVERAGE(FR1_Control!Q2:Q16) -> 0.46666667 | E17: =AVERAGE(FR2_Fast!Q2:Q16) -> 0.33333333 | F17: =AVERAGE(FR3_FilledDelay!Q2:Q16) -> 0.4 | G17: =AVERAGE(FR4_EmptyDelay!Q2:Q16) -> 0.33333333
A18: Vincent_T2 | B18: Vincent | C18: 2 | D18: =AVERAGE(FR1_Control!R2:R16) -> 0.6 | E18: =AVERAGE(FR2_Fast!R2:R16) -> 0.33333333 | F18: =AVERAGE(FR3_FilledDelay!R2:R16) -> 0.33333333 | G18: =AVERAGE(FR4_EmptyDelay!R2:R16) -> 0.33333333
A19: Vincent_T3 | B19: Vincent | C19: 3 | D19: =AVERAGE(FR1_Control!S2:S16) -> 0.46666667 | E19: =AVERAGE(FR2_Fast!S2:S16) -> 0.33333333 | F19: =AVERAGE(FR3_FilledDelay!S2:S16) -> 0.4 | G19: =AVERAGE(FR4_EmptyDelay!S2:S16) -> 0.26666667
A20: Vincent_T4 | B20: Vincent | C20: 4 | D20: =AVERAGE(FR1_Control!T2:T16) -> 0.53333333 | E20: =AVERAGE(FR2_Fast!T2:T16) -> 0.2 | F20: =AVERAGE(FR3_FilledDelay!T2:T16) -> 0.33333333 | G20: =AVERAGE(FR4_EmptyDelay!T2:T16) -> 0.33333333
A21: Vincent_T5 | B21: Vincent | C21: 5 | D21: =AVERAGE(FR1_Control!U2:U16) -> 0.53333333 | E21: =AVERAGE(FR2_Fast!U2:U16) -> 0.26666667 | F21: =AVERAGE(FR3_FilledDelay!U2:U16) -> 0.33333333 | G21: =AVERAGE(FR4_EmptyDelay!U2:U16) -> 0.26666667
A22: Filippa_T1 | B22: Filippa | C22: 1 | D22: =AVERAGE(FR1_Control!V2:V16) -> 0.26666667 | E22: =AVERAGE(FR2_Fast!V2:V16) -> 0.26666667 | F22: =AVERAGE(FR3_FilledDelay!V2:V16) -> 0.2 | G22: =AVERAGE(FR4_EmptyDelay!V2:V16) -> 0.26666667
A23: Filippa_T2 | B23: Filippa | C23: 2 | D23: =AVERAGE(FR1_Control!W2:W16) -> 0.26666667 | E23: =AVERAGE(FR2_Fast!W2:W16) -> 0.26666667 | F23: =AVERAGE(FR3_FilledDelay!W2:W16) -> 0.33333333 | G23: =AVERAGE(FR4_EmptyDelay!W2:W16) -> 0.13333333
A24: Filippa_T3 | B24: Filippa | C24: 3 | D24: =AVERAGE(FR1_Control!X2:X16) -> 0.4 | E24: =AVERAGE(FR2_Fast!X2:X16) -> 0.066666667 | F24: =AVERAGE(FR3_FilledDelay!X2:X16) -> 0.13333333 | G24: =AVERAGE(FR4_EmptyDelay!X2:X16) -> 0.2
A25: Filippa_T4 | B25: Filippa | C25: 4 | D25: =AVERAGE(FR1_Control!Y2:Y16) -> 0.66666667 | E25: =AVERAGE(FR2_Fast!Y2:Y16) -> 0.26666667 | F25: =AVERAGE(FR3_FilledDelay!Y2:Y16) -> 0.2 | G25: =AVERAGE(FR4_EmptyDelay!Y2:Y16) -> 0.26666667
A26: Filippa_T5 | B26: Filippa | C26: 5 | D26: =AVERAGE(FR1_Control!Z2:Z16) -> 0.46666667 | E26: =AVERAGE(FR2_Fast!Z2:Z16) -> 0.2 | F26: =AVERAGE(FR3_FilledDelay!Z2:Z16) -> 0.2 | G26: =AVERAGE(FR4_EmptyDelay!Z2:Z16) -> 0.2

Sheet SR_PositionMeans
A1: Position | B1: SR1_Control | C1: SR2_Chunking | D1: SR3_Suppression | E1: SR4_Tapping
A2: 1 | B2: =SR1_Control!AA2 -> 1 | C2: =SR2_Chunking!AA2 -> 0.96 | D2: =SR3_Suppression!AA2 -> 0.68 | E2: =SR4_Tapping!AA2 -> 0.8
A3: 2 | B3: =SR1_Control!AA3 -> 0.88 | C3: =SR2_Chunking!AA3 -> 0.84 | D3: =SR3_Suppression!AA3 -> 0.76 | E3: =SR4_Tapping!AA3 -> 0.76
A4: 3 | B4: =SR1_Control!AA4 -> 0.72 | C4: =SR2_Chunking!AA4 -> 0.84 | D4: =SR3_Suppression!AA4 -> 0.64 | E4: =SR4_Tapping!AA4 -> 0.6
A5: 4 | B5: =SR1_Control!AA5 -> 0.6 | C5: =SR2_Chunking!AA5 -> 0.76 | D5: =SR3_Suppression!AA5 -> 0.52 | E5: =SR4_Tapping!AA5 -> 0.56
A6: 5 | B6: =SR1_Control!AA6 -> 0.48 | C6: =SR2_Chunking!AA6 -> 0.8 | D6: =SR3_Suppression!AA6 -> 0.2 | E6: =SR4_Tapping!AA6 -> 0.52
A7: 6 | B7: =SR1_Control!AA7 -> 0.52 | C7: =SR2_Chunking!AA7 -> 0.68 | D7: =SR3_Suppression!AA7 -> 0.2 | E7: =SR4_Tapping!AA7 -> 0.36
A8: 7 | B8: =SR1_Control!AA8 -> 0.4 | C8: =SR2_Chunking!AA8 -> 0.6 | D8: =SR3_Suppression!AA8 -> 0.24 | E8: =SR4_Tapping!AA8 -> 0.32
A9: 8 | B9: =SR1_Control!AA9 -> 0.2 | C9: =SR2_Chunking!AA9 -> 0.64 | D9: =SR3_Suppression!AA9 -> 0.12 | E9: =SR4_Tapping!AA9 -> 0.16
A10: 9 | B10: =SR1_Control!AA10 -> 0.08 | C10: =SR2_Chunking!AA10 -> 0.68 | D10: =SR3_Suppression!AA10 -> 0.12 | E10: =SR4_Tapping!AA10 -> 0.2
A11: 10 | B11: =SR1_Control!AA11 -> 0.12 | C11: =SR2_Chunking!AA11 -> 0.44 | D11: =SR3_Suppression!AA11 -> 0.12 | E11: =SR4_Tapping!AA11 -> 0.36
A12: All positions | B12: =AVERAGE(B2:B11) -> 0.5 | C12: =AVERAGE(C2:C11) -> 0.724 | D12: =AVERAGE(D2:D11) -> 0.36 | E12: =AVERAGE(E2:E11) -> 0.464

Sheet SR_TrialScores
A1: Trial ID | B1: Participant | C1: Trial | D1: SR1_Control | E1: SR2_Chunking | F1: SR3_Suppression | G1: SR4_Tapping
A2: Bertram_T1 | B2: Bertram | C2: 1 | D2: =AVERAGE(SR1_Control!B2:B11) -> 0.1 | E2: =AVERAGE(SR2_Chunking!B2:B11) -> 0.8 | F2: =AVERAGE(SR3_Suppression!B2:B11) -> 0.4 | G2: =AVERAGE(SR4_Tapping!B2:B11) -> 0.5
A3: Bertram_T2 | B3: Bertram | C3: 2 | D3: =AVERAGE(SR1_Control!C2:C11) -> 0.4 | E3: =AVERAGE(SR2_Chunking!C2:C11) -> 0.9 | F3: =AVERAGE(SR3_Suppression!C2:C11) -> 0.4 | G3: =AVERAGE(SR4_Tapping!C2:C11) -> 0.5
A4: Bertram_T3 | B4: Bertram | C4: 3 | D4: =AVERAGE(SR1_Control!D2:D11) -> 0.3 | E4: =AVERAGE(SR2_Chunking!D2:D11) -> 0.4 | F4: =AVERAGE(SR3_Suppression!D2:D11) -> 0.4 | G4: =AVERAGE(SR4_Tapping!D2:D11) -> 0.4
A5: Bertram_T4 | B5: Bertram | C5: 4 | D5: =AVERAGE(SR1_Control!E2:E11) -> 0.2 | E5: =AVERAGE(SR2_Chunking!E2:E11) -> 0.5 | F5: =AVERAGE(SR3_Suppression!E2:E11) -> 0.4 | G5: =AVERAGE(SR4_Tapping!E2:E11) -> 0.4
A6: Bertram_T5 | B6: Bertram | C6: 5 | D6: =AVERAGE(SR1_Control!F2:F11) -> 0.5 | E6: =AVERAGE(SR2_Chunking!F2:F11) -> 0.7 | F6: =AVERAGE(SR3_Suppression!F2:F11) -> 0.3 | G6: =AVERAGE(SR4_Tapping!F2:F11) -> 0.4
A7: Lasse_T1 | B7: Lasse | C7: 1 | D7: =AVERAGE(SR1_Control!G2:G11) -> 0.7 | E7: =AVERAGE(SR2_Chunking!G2:G11) -> 0.6 | F7: =AVERAGE(SR3_Suppression!G2:G11) -> 0.2 | G7: =AVERAGE(SR4_Tapping!G2:G11) -> 0.3
A8: Lasse_T2 | B8: Lasse | C8: 2 | D8: =AVERAGE(SR1_Control!H2:H11) -> 0.4 | E8: =AVERAGE(SR2_Chunking!H2:H11) -> 0.7 | F8: =AVERAGE(SR3_Suppression!H2:H11) -> 0.4 | G8: =AVERAGE(SR4_Tapping!H2:H11) -> 0.5
A9: Lasse_T3 | B9: Lasse | C9: 3 | D9: =AVERAGE(SR1_Control!I2:I11) -> 0.5 | E9: =AVERAGE(SR2_Chunking!I2:I11) -> 0.5 | F9: =AVERAGE(SR3_Suppression!I2:I11) -> 0.5 | G9: =AVERAGE(SR4_Tapping!I2:I11) -> 0.4
A10: Lasse_T4 | B10: Lasse | C10: 4 | D10: =AVERAGE(SR1_Control!J2:J11) -> 0.4 | E10: =AVERAGE(SR2_Chunking!J2:J11) -> 0.6 | F10: =AVERAGE(SR3_Suppression!J2:J11) -> 0.3 | G10: =AVERAGE(SR4_Tapping!J2:J11) -> 0.5
A11: Lasse_T5 | B11: Lasse | C11: 5 | D11: =AVERAGE(SR1_Control!K2:K11) -> 0.3 | E11: =AVERAGE(SR2_Chunking!K2:K11) -> 0.5 | F11: =AVERAGE(SR3_Suppression!K2:K11) -> 0.4 | G11: =AVERAGE(SR4_Tapping!K2:K11) -> 0.4
A12: Noah_T1 | B12: Noah | C12: 1 | D12: =AVERAGE(SR1_Control!L2:L11) -> 0.5 | E12: =AVERAGE(SR2_Chunking!L2:L11) -> 0.5 | F12: =AVERAGE(SR3_Suppression!L2:L11) -> 0.3 | G12: =AVERAGE(SR4_Tapping!L2:L11) -> 0.5
A13: Noah_T2 | B13: Noah | C13: 2 | D13: =AVERAGE(SR1_Control!M2:M11) -> 0.7 | E13: =AVERAGE(SR2_Chunking!M2:M11) -> 1 | F13: =AVERAGE(SR3_Suppression!M2:M11) -> 0.4 | G13: =AVERAGE(SR4_Tapping!M2:M11) -> 0.7
A14: Noah_T3 | B14: Noah | C14: 3 | D14: =AVERAGE(SR1_Control!N2:N11) -> 0.6 | E14: =AVERAGE(SR2_Chunking!N2:N11) -> 1 | F14: =AVERAGE(SR3_Suppression!N2:N11) -> 0.3 | G14: =AVERAGE(SR4_Tapping!N2:N11) -> 0.7
A15: Noah_T4 | B15: Noah | C15: 4 | D15: =AVERAGE(SR1_Control!O2:O11) -> 0.7 | E15: =AVERAGE(SR2_Chunking!O2:O11) -> 1 | F15: =AVERAGE(SR3_Suppression!O2:O11) -> 0.4 | G15: =AVERAGE(SR4_Tapping!O2:O11) -> 0.3
A16: Noah_T5 | B16: Noah | C16: 5 | D16: =AVERAGE(SR1_Control!P2:P11) -> 0.8 | E16: =AVERAGE(SR2_Chunking!P2:P11) -> 1 | F16: =AVERAGE(SR3_Suppression!P2:P11) -> 0.4 | G16: =AVERAGE(SR4_Tapping!P2:P11) -> 0.5
A17: Vincent_T1 | B17: Vincent | C17: 1 | D17: =AVERAGE(SR1_Control!Q2:Q11) -> 0.7 | E17: =AVERAGE(SR2_Chunking!Q2:Q11) -> 0.7 | F17: =AVERAGE(SR3_Suppression!Q2:Q11) -> 0.5 | G17: =AVERAGE(SR4_Tapping!Q2:Q11) -> 0.6
A18: Vincent_T2 | B18: Vincent | C18: 2 | D18: =AVERAGE(SR1_Control!R2:R11) -> 0.6 | E18: =AVERAGE(SR2_Chunking!R2:R11) -> 0.9 | F18: =AVERAGE(SR3_Suppression!R2:R11) -> 0.4 | G18: =AVERAGE(SR4_Tapping!R2:R11) -> 0.4
A19: Vincent_T3 | B19: Vincent | C19: 3 | D19: =AVERAGE(SR1_Control!S2:S11) -> 0.8 | E19: =AVERAGE(SR2_Chunking!S2:S11) -> 1 | F19: =AVERAGE(SR3_Suppression!S2:S11) -> 0.4 | G19: =AVERAGE(SR4_Tapping!S2:S11) -> 0.7
A20: Vincent_T4 | B20: Vincent | C20: 4 | D20: =AVERAGE(SR1_Control!T2:T11) -> 0.6 | E20: =AVERAGE(SR2_Chunking!T2:T11) -> 1 | F20: =AVERAGE(SR3_Suppression!T2:T11) -> 0.3 | G20: =AVERAGE(SR4_Tapping!T2:T11) -> 0.6
A21: Vincent_T5 | B21: Vincent | C21: 5 | D21: =AVERAGE(SR1_Control!U2:U11) -> 0.5 | E21: =AVERAGE(SR2_Chunking!U2:U11) -> 0.8 | F21: =AVERAGE(SR3_Suppression!U2:U11) -> 0.3 | G21: =AVERAGE(SR4_Tapping!U2:U11) -> 0.5
A22: Filippa_T1 | B22: Filippa | C22: 1 | D22: =AVERAGE(SR1_Control!V2:V11) -> 0.4 | E22: =AVERAGE(SR2_Chunking!V2:V11) -> 0.5 | F22: =AVERAGE(SR3_Suppression!V2:V11) -> 0.2 | G22: =AVERAGE(SR4_Tapping!V2:V11) -> 0.3
A23: Filippa_T2 | B23: Filippa | C23: 2 | D23: =AVERAGE(SR1_Control!W2:W11) -> 0.5 | E23: =AVERAGE(SR2_Chunking!W2:W11) -> 0.6 | F23: =AVERAGE(SR3_Suppression!W2:W11) -> 0.3 | G23: =AVERAGE(SR4_Tapping!W2:W11) -> 0.4
A24: Filippa_T3 | B24: Filippa | C24: 3 | D24: =AVERAGE(SR1_Control!X2:X11) -> 0.5 | E24: =AVERAGE(SR2_Chunking!X2:X11) -> 0.2 | F24: =AVERAGE(SR3_Suppression!X2:X11) -> 0.4 | G24: =AVERAGE(SR4_Tapping!X2:X11) -> 0.3
A25: Filippa_T4 | B25: Filippa | C25: 4 | D25: =AVERAGE(SR1_Control!Y2:Y11) -> 0.3 | E25: =AVERAGE(SR2_Chunking!Y2:Y11) -> 0.9 | F25: =AVERAGE(SR3_Suppression!Y2:Y11) -> 0.3 | G25: =AVERAGE(SR4_Tapping!Y2:Y11) -> 0.4
A26: Filippa_T5 | B26: Filippa | C26: 5 | D26: =AVERAGE(SR1_Control!Z2:Z11) -> 0.5 | E26: =AVERAGE(SR2_Chunking!Z2:Z11) -> 0.8 | F26: =AVERAGE(SR3_Suppression!Z2:Z11) -> 0.4 | G26: =AVERAGE(SR4_Tapping!Z2:Z11) -> 0.4

Sheet Pilot_FR
A1: Position | B1: FR1_Control | C1: FR2_Fast | D1: FR3_FilledDelay | E1: FR4_EmptyDelay
A2: 1 | B2: 1 | C2: 1 | D2: 1 | E2: 0
A3: 2 | B3: 0 | C3: 0 | D3: 0 | E3: 0
A4: 3 | B4: 1 | C4: 1 | D4: 1 | E4: 0
A5: 4 | B5: 1 | C5: 0 | D5: 0 | E5: 0
A6: 5 | B6: 0 | C6: 1 | D6: 1 | E6: 1
A7: 6 | B7: 1 | C7: 0 | D7: 0 | E7: 0
A8: 7 | B8: 0 | C8: 0 | D8: 1 | E8: 0
A9: 8 | B9: 0 | C9: 0 | D9: 0 | E9: 0
A10: 9 | B10: 1 | C10: 0 | D10: 0 | E10: 1
A11: 10 | B11: 1 | C11: 1 | D11: 1 | E11: 1
A12: 11 | B12: 0 | C12: 0 | D12: 0 | E12: 0
A13: 12 | B13: 0 | C13: 1 | D13: 1 | E13: 0
... A16: 15 | B16: 0 | C16: 0 | D16: 1 | E16: 0
